
user=jungsoo
date=2023-12-01 16:40:09
contents_name='유료상점'
doctype='TestCase'
date_text='2023-12-12'
Traceback (most recent call last):
  File "C:\Users\jungsoo\OneDrive - Webzen Inc\R2M전용도구\유료상점CL생성기\RDM.py", line 140, in make_process
    data = ClCash.extract_data_cashshop(data_file_name, date_text)
           ^^^^^^^^^^^^^^^^^^^^^^^^^^^^^^^^^^^^^^^^^^^^^^^^^^^^^^^
  File "C:\Users\jungsoo\OneDrive - Webzen Inc\R2M전용도구\유료상점CL생성기\CLMaker_cashshop.py", line 142, in extract_data_cashshop
    sheet_names = pd.ExcelFile(fileName).sheet_names
                  ^^^^^^^^^^^^^^^^^^^^^^
  File "C:\Users\jungsoo\AppData\Local\Programs\Python\Python311\Lib\site-packages\pandas\io\excel\_base.py", line 1652, in __init__
    ext = inspect_excel_format(
          ^^^^^^^^^^^^^^^^^^^^^
  File "C:\Users\jungsoo\AppData\Local\Programs\Python\Python311\Lib\site-packages\pandas\io\excel\_base.py", line 1525, in inspect_excel_format
    with get_handle(
         ^^^^^^^^^^^
  File "C:\Users\jungsoo\AppData\Local\Programs\Python\Python311\Lib\site-packages\pandas\io\common.py", line 865, in get_handle
    handle = open(handle, ioargs.mode)
             ^^^^^^^^^^^^^^^^^^^^^^^^^
PermissionError: [Errno 13] Permission denied: '유료상점DATA_TW R2M.xlsx'

────────────────────────────────────────

user=jungsoo
date=2023-12-01 16:39:39
contents_name='유료상점'
doctype='TestCase'
date_text='2023-12-12'
Traceback (most recent call last):
  File "C:\Users\jungsoo\OneDrive - Webzen Inc\R2M전용도구\유료상점CL생성기\RDM.py", line 140, in make_process
    data = ClCash.extract_data_cashshop(data_file_name, date_text)
           ^^^^^^^^^^^^^^^^^^^^^^^^^^^^^^^^^^^^^^^^^^^^^^^^^^^^^^^
  File "C:\Users\jungsoo\OneDrive - Webzen Inc\R2M전용도구\유료상점CL생성기\CLMaker_cashshop.py", line 142, in extract_data_cashshop
    sheet_names = pd.ExcelFile(fileName).sheet_names
                  ^^^^^^^^^^^^^^^^^^^^^^
  File "C:\Users\jungsoo\AppData\Local\Programs\Python\Python311\Lib\site-packages\pandas\io\excel\_base.py", line 1652, in __init__
    ext = inspect_excel_format(
          ^^^^^^^^^^^^^^^^^^^^^
  File "C:\Users\jungsoo\AppData\Local\Programs\Python\Python311\Lib\site-packages\pandas\io\excel\_base.py", line 1525, in inspect_excel_format
    with get_handle(
         ^^^^^^^^^^^
  File "C:\Users\jungsoo\AppData\Local\Programs\Python\Python311\Lib\site-packages\pandas\io\common.py", line 865, in get_handle
    handle = open(handle, ioargs.mode)
             ^^^^^^^^^^^^^^^^^^^^^^^^^
PermissionError: [Errno 13] Permission denied: '유료상점DATA_TW R2M.xlsx'

────────────────────────────────────────

user=mssung
date=2023-12-01 16:38:48
contents_name='유료상점'
doctype='TestCase'
date_text='2023-12-12'
Traceback (most recent call last):
  File "C:\Users\mssung\OneDrive - Webzen Inc\R2M도구\유료상점CL생성기\RDM.py", line 140, in make_process
    data = ClCash.extract_data_cashshop(data_file_name, date_text)
  File "C:\Users\mssung\OneDrive - Webzen Inc\R2M도구\유료상점CL생성기\CLMaker_cashshop.py", line 142, in extract_data_cashshop
    sheet_names = pd.ExcelFile(fileName).sheet_names
  File "C:\Python39\lib\site-packages\pandas\io\excel\_base.py", line 1191, in __init__
    ext = inspect_excel_format(
  File "C:\Python39\lib\site-packages\pandas\io\excel\_base.py", line 1070, in inspect_excel_format
    with get_handle(
  File "C:\Python39\lib\site-packages\pandas\io\common.py", line 711, in get_handle
    handle = open(handle, ioargs.mode)
PermissionError: [Errno 13] Permission denied: '유료상점DATA_TW R2M.xlsx'

────────────────────────────────────────

user=mssung
date=2023-12-01 16:38:40
contents_name='유료상점'
doctype='TestCase'
date_text='2023-12-12'
Traceback (most recent call last):
  File "C:\Users\mssung\OneDrive - Webzen Inc\R2M도구\유료상점CL생성기\RDM.py", line 140, in make_process
    data = ClCash.extract_data_cashshop(data_file_name, date_text)
  File "C:\Users\mssung\OneDrive - Webzen Inc\R2M도구\유료상점CL생성기\CLMaker_cashshop.py", line 142, in extract_data_cashshop
    sheet_names = pd.ExcelFile(fileName).sheet_names
  File "C:\Python39\lib\site-packages\pandas\io\excel\_base.py", line 1191, in __init__
    ext = inspect_excel_format(
  File "C:\Python39\lib\site-packages\pandas\io\excel\_base.py", line 1070, in inspect_excel_format
    with get_handle(
  File "C:\Python39\lib\site-packages\pandas\io\common.py", line 711, in get_handle
    handle = open(handle, ioargs.mode)
PermissionError: [Errno 13] Permission denied: '유료상점DATA_KR R2M.xlsx'

────────────────────────────────────────

user=jungsoo
date=2023-12-01 15:54:18
contents_name='유료상점'
doctype='TestCase'
date_text='2023-12-12'
Traceback (most recent call last):
  File "C:\Users\jungsoo\AppData\Local\Programs\Python\Python311\Lib\site-packages\pandas\core\indexes\base.py", line 3802, in get_loc
    return self._engine.get_loc(casted_key)
           ^^^^^^^^^^^^^^^^^^^^^^^^^^^^^^^^
  File "pandas\_libs\index.pyx", line 138, in pandas._libs.index.IndexEngine.get_loc
  File "pandas\_libs\index.pyx", line 165, in pandas._libs.index.IndexEngine.get_loc
  File "pandas\_libs\hashtable_class_helper.pxi", line 5745, in pandas._libs.hashtable.PyObjectHashTable.get_item
  File "pandas\_libs\hashtable_class_helper.pxi", line 5753, in pandas._libs.hashtable.PyObjectHashTable.get_item
KeyError: 'Order'

The above exception was the direct cause of the following exception:

Traceback (most recent call last):
  File "C:\Users\jungsoo\OneDrive - Webzen Inc\R2M전용도구\유료상점CL생성기\RDM.py", line 140, in make_process
    data = ClCash.extract_data_cashshop(data_file_name, date_text)
           ^^^^^^^^^^^^^^^^^^^^^^^^^^^^^^^^^^^^^^^^^^^^^^^^^^^^^^^
  File "C:\Users\jungsoo\OneDrive - Webzen Inc\R2M전용도구\유료상점CL생성기\CLMaker_cashshop.py", line 207, in extract_data_cashshop
    a.order = tempDf.loc[0,"Order"]
              ~~~~~~~~~~^^^^^^^^^^^
  File "C:\Users\jungsoo\AppData\Local\Programs\Python\Python311\Lib\site-packages\pandas\core\indexing.py", line 1066, in __getitem__
    return self.obj._get_value(*key, takeable=self._takeable)
           ^^^^^^^^^^^^^^^^^^^^^^^^^^^^^^^^^^^^^^^^^^^^^^^^^^
  File "C:\Users\jungsoo\AppData\Local\Programs\Python\Python311\Lib\site-packages\pandas\core\frame.py", line 3917, in _get_value
    series = self._get_item_cache(col)
             ^^^^^^^^^^^^^^^^^^^^^^^^^
  File "C:\Users\jungsoo\AppData\Local\Programs\Python\Python311\Lib\site-packages\pandas\core\frame.py", line 4282, in _get_item_cache
    loc = self.columns.get_loc(item)
          ^^^^^^^^^^^^^^^^^^^^^^^^^^
  File "C:\Users\jungsoo\AppData\Local\Programs\Python\Python311\Lib\site-packages\pandas\core\indexes\base.py", line 3804, in get_loc
    raise KeyError(key) from err
KeyError: 'Order'

────────────────────────────────────────

user=jungsoo
date=2023-12-01 09:52:28
contents_name='유료상점'
doctype='TestCase'
date_text='2023-12-12'
Traceback (most recent call last):
  File "C:\Users\jungsoo\AppData\Local\Programs\Python\Python311\Lib\site-packages\pandas\core\indexes\base.py", line 3802, in get_loc
    return self._engine.get_loc(casted_key)
           ^^^^^^^^^^^^^^^^^^^^^^^^^^^^^^^^
  File "pandas\_libs\index.pyx", line 138, in pandas._libs.index.IndexEngine.get_loc
  File "pandas\_libs\index.pyx", line 165, in pandas._libs.index.IndexEngine.get_loc
  File "pandas\_libs\hashtable_class_helper.pxi", line 5745, in pandas._libs.hashtable.PyObjectHashTable.get_item
  File "pandas\_libs\hashtable_class_helper.pxi", line 5753, in pandas._libs.hashtable.PyObjectHashTable.get_item
KeyError: 'Order'

The above exception was the direct cause of the following exception:

Traceback (most recent call last):
  File "C:\Users\jungsoo\OneDrive - Webzen Inc\R2M전용도구\유료상점CL생성기\RDM.py", line 140, in make_process
    data = ClCash.extract_data_cashshop(data_file_name, date_text)
           ^^^^^^^^^^^^^^^^^^^^^^^^^^^^^^^^^^^^^^^^^^^^^^^^^^^^^^^
  File "C:\Users\jungsoo\OneDrive - Webzen Inc\R2M전용도구\유료상점CL생성기\CLMaker_cashshop.py", line 207, in extract_data_cashshop
    a.order = tempDf.loc[0,"Order"]
              ~~~~~~~~~~^^^^^^^^^^^
  File "C:\Users\jungsoo\AppData\Local\Programs\Python\Python311\Lib\site-packages\pandas\core\indexing.py", line 1066, in __getitem__
    return self.obj._get_value(*key, takeable=self._takeable)
           ^^^^^^^^^^^^^^^^^^^^^^^^^^^^^^^^^^^^^^^^^^^^^^^^^^
  File "C:\Users\jungsoo\AppData\Local\Programs\Python\Python311\Lib\site-packages\pandas\core\frame.py", line 3917, in _get_value
    series = self._get_item_cache(col)
             ^^^^^^^^^^^^^^^^^^^^^^^^^
  File "C:\Users\jungsoo\AppData\Local\Programs\Python\Python311\Lib\site-packages\pandas\core\frame.py", line 4282, in _get_item_cache
    loc = self.columns.get_loc(item)
          ^^^^^^^^^^^^^^^^^^^^^^^^^^
  File "C:\Users\jungsoo\AppData\Local\Programs\Python\Python311\Lib\site-packages\pandas\core\indexes\base.py", line 3804, in get_loc
    raise KeyError(key) from err
KeyError: 'Order'

────────────────────────────────────────

user=jungsoo
date=2023-12-01 09:52:07
contents_name='유료상점'
doctype='TestCase'
date_text='2023-12-12'
Traceback (most recent call last):
  File "C:\Users\jungsoo\AppData\Local\Programs\Python\Python311\Lib\site-packages\pandas\core\indexes\base.py", line 3802, in get_loc
    return self._engine.get_loc(casted_key)
           ^^^^^^^^^^^^^^^^^^^^^^^^^^^^^^^^
  File "pandas\_libs\index.pyx", line 138, in pandas._libs.index.IndexEngine.get_loc
  File "pandas\_libs\index.pyx", line 165, in pandas._libs.index.IndexEngine.get_loc
  File "pandas\_libs\hashtable_class_helper.pxi", line 5745, in pandas._libs.hashtable.PyObjectHashTable.get_item
  File "pandas\_libs\hashtable_class_helper.pxi", line 5753, in pandas._libs.hashtable.PyObjectHashTable.get_item
KeyError: 'Order'

The above exception was the direct cause of the following exception:

Traceback (most recent call last):
  File "C:\Users\jungsoo\OneDrive - Webzen Inc\R2M전용도구\유료상점CL생성기\RDM.py", line 140, in make_process
    data = ClCash.extract_data_cashshop(data_file_name, date_text)
           ^^^^^^^^^^^^^^^^^^^^^^^^^^^^^^^^^^^^^^^^^^^^^^^^^^^^^^^
  File "C:\Users\jungsoo\OneDrive - Webzen Inc\R2M전용도구\유료상점CL생성기\CLMaker_cashshop.py", line 207, in extract_data_cashshop
    a.order = tempDf.loc[0,"Order"]
              ~~~~~~~~~~^^^^^^^^^^^
  File "C:\Users\jungsoo\AppData\Local\Programs\Python\Python311\Lib\site-packages\pandas\core\indexing.py", line 1066, in __getitem__
    return self.obj._get_value(*key, takeable=self._takeable)
           ^^^^^^^^^^^^^^^^^^^^^^^^^^^^^^^^^^^^^^^^^^^^^^^^^^
  File "C:\Users\jungsoo\AppData\Local\Programs\Python\Python311\Lib\site-packages\pandas\core\frame.py", line 3917, in _get_value
    series = self._get_item_cache(col)
             ^^^^^^^^^^^^^^^^^^^^^^^^^
  File "C:\Users\jungsoo\AppData\Local\Programs\Python\Python311\Lib\site-packages\pandas\core\frame.py", line 4282, in _get_item_cache
    loc = self.columns.get_loc(item)
          ^^^^^^^^^^^^^^^^^^^^^^^^^^
  File "C:\Users\jungsoo\AppData\Local\Programs\Python\Python311\Lib\site-packages\pandas\core\indexes\base.py", line 3804, in get_loc
    raise KeyError(key) from err
KeyError: 'Order'

────────────────────────────────────────

user=jungsoo
date=2023-11-30 16:22:15
contents_name='유료상점'
doctype='TestCase'
date_text='2023-12-12'
Traceback (most recent call last):
  File "C:\Users\jungsoo\AppData\Local\Programs\Python\Python311\Lib\site-packages\pandas\core\indexes\base.py", line 3802, in get_loc
    return self._engine.get_loc(casted_key)
           ^^^^^^^^^^^^^^^^^^^^^^^^^^^^^^^^
  File "pandas\_libs\index.pyx", line 138, in pandas._libs.index.IndexEngine.get_loc
  File "pandas\_libs\index.pyx", line 165, in pandas._libs.index.IndexEngine.get_loc
  File "pandas\_libs\hashtable_class_helper.pxi", line 5745, in pandas._libs.hashtable.PyObjectHashTable.get_item
  File "pandas\_libs\hashtable_class_helper.pxi", line 5753, in pandas._libs.hashtable.PyObjectHashTable.get_item
KeyError: 'Order'

The above exception was the direct cause of the following exception:

Traceback (most recent call last):
  File "C:\Users\jungsoo\OneDrive - Webzen Inc\R2M전용도구\유료상점CL생성기\RDM.py", line 140, in make_process
    data = ClCash.extract_data_cashshop(data_file_name, date_text)
           ^^^^^^^^^^^^^^^^^^^^^^^^^^^^^^^^^^^^^^^^^^^^^^^^^^^^^^^
  File "C:\Users\jungsoo\OneDrive - Webzen Inc\R2M전용도구\유료상점CL생성기\CLMaker_cashshop.py", line 207, in extract_data_cashshop
    a.order = tempDf.loc[0,"Order"]
              ~~~~~~~~~~^^^^^^^^^^^
  File "C:\Users\jungsoo\AppData\Local\Programs\Python\Python311\Lib\site-packages\pandas\core\indexing.py", line 1066, in __getitem__
    return self.obj._get_value(*key, takeable=self._takeable)
           ^^^^^^^^^^^^^^^^^^^^^^^^^^^^^^^^^^^^^^^^^^^^^^^^^^
  File "C:\Users\jungsoo\AppData\Local\Programs\Python\Python311\Lib\site-packages\pandas\core\frame.py", line 3917, in _get_value
    series = self._get_item_cache(col)
             ^^^^^^^^^^^^^^^^^^^^^^^^^
  File "C:\Users\jungsoo\AppData\Local\Programs\Python\Python311\Lib\site-packages\pandas\core\frame.py", line 4282, in _get_item_cache
    loc = self.columns.get_loc(item)
          ^^^^^^^^^^^^^^^^^^^^^^^^^^
  File "C:\Users\jungsoo\AppData\Local\Programs\Python\Python311\Lib\site-packages\pandas\core\indexes\base.py", line 3804, in get_loc
    raise KeyError(key) from err
KeyError: 'Order'

────────────────────────────────────────

user=jungsoo
date=2023-11-30 16:21:12
contents_name='유료상점'
doctype='TestCase'
date_text='2023-12-12'
Traceback (most recent call last):
  File "C:\Users\jungsoo\AppData\Local\Programs\Python\Python311\Lib\site-packages\pandas\core\indexes\base.py", line 3802, in get_loc
    return self._engine.get_loc(casted_key)
           ^^^^^^^^^^^^^^^^^^^^^^^^^^^^^^^^
  File "pandas\_libs\index.pyx", line 138, in pandas._libs.index.IndexEngine.get_loc
  File "pandas\_libs\index.pyx", line 165, in pandas._libs.index.IndexEngine.get_loc
  File "pandas\_libs\hashtable_class_helper.pxi", line 5745, in pandas._libs.hashtable.PyObjectHashTable.get_item
  File "pandas\_libs\hashtable_class_helper.pxi", line 5753, in pandas._libs.hashtable.PyObjectHashTable.get_item
KeyError: 'Order'

The above exception was the direct cause of the following exception:

Traceback (most recent call last):
  File "C:\Users\jungsoo\OneDrive - Webzen Inc\R2M전용도구\유료상점CL생성기\RDM.py", line 140, in make_process
    data = ClCash.extract_data_cashshop(data_file_name, date_text)
           ^^^^^^^^^^^^^^^^^^^^^^^^^^^^^^^^^^^^^^^^^^^^^^^^^^^^^^^
  File "C:\Users\jungsoo\OneDrive - Webzen Inc\R2M전용도구\유료상점CL생성기\CLMaker_cashshop.py", line 207, in extract_data_cashshop
    a.order = tempDf.loc[0,"Order"]
              ~~~~~~~~~~^^^^^^^^^^^
  File "C:\Users\jungsoo\AppData\Local\Programs\Python\Python311\Lib\site-packages\pandas\core\indexing.py", line 1066, in __getitem__
    return self.obj._get_value(*key, takeable=self._takeable)
           ^^^^^^^^^^^^^^^^^^^^^^^^^^^^^^^^^^^^^^^^^^^^^^^^^^
  File "C:\Users\jungsoo\AppData\Local\Programs\Python\Python311\Lib\site-packages\pandas\core\frame.py", line 3917, in _get_value
    series = self._get_item_cache(col)
             ^^^^^^^^^^^^^^^^^^^^^^^^^
  File "C:\Users\jungsoo\AppData\Local\Programs\Python\Python311\Lib\site-packages\pandas\core\frame.py", line 4282, in _get_item_cache
    loc = self.columns.get_loc(item)
          ^^^^^^^^^^^^^^^^^^^^^^^^^^
  File "C:\Users\jungsoo\AppData\Local\Programs\Python\Python311\Lib\site-packages\pandas\core\indexes\base.py", line 3804, in get_loc
    raise KeyError(key) from err
KeyError: 'Order'

────────────────────────────────────────

user=jungsoo
date=2023-11-30 16:20:45
contents_name='유료상점'
doctype='TestCase'
date_text='2023-12-12'
Traceback (most recent call last):
  File "C:\Users\jungsoo\AppData\Local\Programs\Python\Python311\Lib\site-packages\pandas\core\indexes\base.py", line 3802, in get_loc
    return self._engine.get_loc(casted_key)
           ^^^^^^^^^^^^^^^^^^^^^^^^^^^^^^^^
  File "pandas\_libs\index.pyx", line 138, in pandas._libs.index.IndexEngine.get_loc
  File "pandas\_libs\index.pyx", line 165, in pandas._libs.index.IndexEngine.get_loc
  File "pandas\_libs\hashtable_class_helper.pxi", line 5745, in pandas._libs.hashtable.PyObjectHashTable.get_item
  File "pandas\_libs\hashtable_class_helper.pxi", line 5753, in pandas._libs.hashtable.PyObjectHashTable.get_item
KeyError: 'Order'

The above exception was the direct cause of the following exception:

Traceback (most recent call last):
  File "C:\Users\jungsoo\OneDrive - Webzen Inc\R2M전용도구\유료상점CL생성기\RDM.py", line 140, in make_process
    data = ClCash.extract_data_cashshop(data_file_name, date_text)
           ^^^^^^^^^^^^^^^^^^^^^^^^^^^^^^^^^^^^^^^^^^^^^^^^^^^^^^^
  File "C:\Users\jungsoo\OneDrive - Webzen Inc\R2M전용도구\유료상점CL생성기\CLMaker_cashshop.py", line 207, in extract_data_cashshop
    a.order = tempDf.loc[0,"Order"]
              ~~~~~~~~~~^^^^^^^^^^^
  File "C:\Users\jungsoo\AppData\Local\Programs\Python\Python311\Lib\site-packages\pandas\core\indexing.py", line 1066, in __getitem__
    return self.obj._get_value(*key, takeable=self._takeable)
           ^^^^^^^^^^^^^^^^^^^^^^^^^^^^^^^^^^^^^^^^^^^^^^^^^^
  File "C:\Users\jungsoo\AppData\Local\Programs\Python\Python311\Lib\site-packages\pandas\core\frame.py", line 3917, in _get_value
    series = self._get_item_cache(col)
             ^^^^^^^^^^^^^^^^^^^^^^^^^
  File "C:\Users\jungsoo\AppData\Local\Programs\Python\Python311\Lib\site-packages\pandas\core\frame.py", line 4282, in _get_item_cache
    loc = self.columns.get_loc(item)
          ^^^^^^^^^^^^^^^^^^^^^^^^^^
  File "C:\Users\jungsoo\AppData\Local\Programs\Python\Python311\Lib\site-packages\pandas\core\indexes\base.py", line 3804, in get_loc
    raise KeyError(key) from err
KeyError: 'Order'

────────────────────────────────────────

user=jungsoo
date=2023-11-30 16:20:34
contents_name='유료상점'
doctype='TestCase'
date_text='2023-12-12'
Traceback (most recent call last):
  File "C:\Users\jungsoo\AppData\Local\Programs\Python\Python311\Lib\site-packages\pandas\core\indexes\base.py", line 3802, in get_loc
    return self._engine.get_loc(casted_key)
           ^^^^^^^^^^^^^^^^^^^^^^^^^^^^^^^^
  File "pandas\_libs\index.pyx", line 138, in pandas._libs.index.IndexEngine.get_loc
  File "pandas\_libs\index.pyx", line 165, in pandas._libs.index.IndexEngine.get_loc
  File "pandas\_libs\hashtable_class_helper.pxi", line 5745, in pandas._libs.hashtable.PyObjectHashTable.get_item
  File "pandas\_libs\hashtable_class_helper.pxi", line 5753, in pandas._libs.hashtable.PyObjectHashTable.get_item
KeyError: 'Order'

The above exception was the direct cause of the following exception:

Traceback (most recent call last):
  File "C:\Users\jungsoo\OneDrive - Webzen Inc\R2M전용도구\유료상점CL생성기\RDM.py", line 140, in make_process
    data = ClCash.extract_data_cashshop(data_file_name, date_text)
           ^^^^^^^^^^^^^^^^^^^^^^^^^^^^^^^^^^^^^^^^^^^^^^^^^^^^^^^
  File "C:\Users\jungsoo\OneDrive - Webzen Inc\R2M전용도구\유료상점CL생성기\CLMaker_cashshop.py", line 207, in extract_data_cashshop
    a.order = tempDf.loc[0,"Order"]
              ~~~~~~~~~~^^^^^^^^^^^
  File "C:\Users\jungsoo\AppData\Local\Programs\Python\Python311\Lib\site-packages\pandas\core\indexing.py", line 1066, in __getitem__
    return self.obj._get_value(*key, takeable=self._takeable)
           ^^^^^^^^^^^^^^^^^^^^^^^^^^^^^^^^^^^^^^^^^^^^^^^^^^
  File "C:\Users\jungsoo\AppData\Local\Programs\Python\Python311\Lib\site-packages\pandas\core\frame.py", line 3917, in _get_value
    series = self._get_item_cache(col)
             ^^^^^^^^^^^^^^^^^^^^^^^^^
  File "C:\Users\jungsoo\AppData\Local\Programs\Python\Python311\Lib\site-packages\pandas\core\frame.py", line 4282, in _get_item_cache
    loc = self.columns.get_loc(item)
          ^^^^^^^^^^^^^^^^^^^^^^^^^^
  File "C:\Users\jungsoo\AppData\Local\Programs\Python\Python311\Lib\site-packages\pandas\core\indexes\base.py", line 3804, in get_loc
    raise KeyError(key) from err
KeyError: 'Order'

────────────────────────────────────────

user=mssung
date=2023-11-30 10:42:26
contents_name='이벤트'
doctype='CheckList'
date_text='2023-11-23'
Traceback (most recent call last):
  File "C:\Users\mssung\OneDrive - Webzen Inc\R2M도구\유료상점CL생성기\RDM.py", line 148, in make_process
    data = ClEvent.extract_data(data_file_name, date_text)
  File "C:\Users\mssung\OneDrive - Webzen Inc\R2M도구\유료상점CL생성기\CLMaker_Event.py", line 103, in extract_data
    sheet_names = pd.read_excel(fileName, sheet_name=None).keys()
  File "C:\Python39\lib\site-packages\pandas\util\_decorators.py", line 311, in wrapper
    return func(*args, **kwargs)
  File "C:\Python39\lib\site-packages\pandas\io\excel\_base.py", line 364, in read_excel
    io = ExcelFile(io, storage_options=storage_options, engine=engine)
  File "C:\Python39\lib\site-packages\pandas\io\excel\_base.py", line 1191, in __init__
    ext = inspect_excel_format(
  File "C:\Python39\lib\site-packages\pandas\io\excel\_base.py", line 1070, in inspect_excel_format
    with get_handle(
  File "C:\Python39\lib\site-packages\pandas\io\common.py", line 711, in get_handle
    handle = open(handle, ioargs.mode)
PermissionError: [Errno 13] Permission denied: '이벤트DATA_KR R2M.xlsx'

────────────────────────────────────────

user=mssung
date=2023-11-29 16:29:09
contents_name='이벤트'
doctype='CheckList'
date_text='2023-11-30'
Traceback (most recent call last):
  File "C:\Users\mssung\OneDrive - Webzen Inc\R2M도구\유료상점CL생성기\RDM.py", line 137, in make_process
    result_file_name = ClEvent.write_data(data,result_path,check_box_list)
  File "C:\Users\mssung\OneDrive - Webzen Inc\R2M도구\유료상점CL생성기\CLMaker_Event.py", line 664, in write_data
    info += f'\n{item.name}\n제한:{craft.limit}, 비용:{int(craft.price)}\n'
ValueError: cannot convert float NaN to integer

────────────────────────────────────────

user=mssung
date=2023-11-29 15:28:12
contents_name='이벤트'
doctype='TestCase'
date_text='2023-11-30'
Traceback (most recent call last):
  File "C:\Users\mssung\OneDrive - Webzen Inc\R2M도구\유료상점CL생성기\RDM.py", line 140, in make_process
    data = ClEvent.extract_data(data_file_name,date_text)
  File "C:\Users\mssung\OneDrive - Webzen Inc\R2M도구\유료상점CL생성기\CLMaker_Event.py", line 103, in extract_data
    sheet_names = pd.read_excel(fileName, sheet_name=None).keys()
  File "C:\Python39\lib\site-packages\pandas\util\_decorators.py", line 311, in wrapper
    return func(*args, **kwargs)
  File "C:\Python39\lib\site-packages\pandas\io\excel\_base.py", line 364, in read_excel
    io = ExcelFile(io, storage_options=storage_options, engine=engine)
  File "C:\Python39\lib\site-packages\pandas\io\excel\_base.py", line 1191, in __init__
    ext = inspect_excel_format(
  File "C:\Python39\lib\site-packages\pandas\io\excel\_base.py", line 1070, in inspect_excel_format
    with get_handle(
  File "C:\Python39\lib\site-packages\pandas\io\common.py", line 711, in get_handle
    handle = open(handle, ioargs.mode)
PermissionError: [Errno 13] Permission denied: '이벤트DATA_KR R2M.xlsx'

────────────────────────────────────────

user=mssung
date=2023-11-27 12:06:03
contents_name='유료상점'
doctype='TestCase'
date_text='2023-11-30'
Traceback (most recent call last):
  File "C:\Users\mssung\OneDrive - Webzen Inc\R2M도구\유료상점CL생성기\RDM.py", line 128, in make_process
    data = ClCash.extract_data_cashshop(data_file_name, date_text)
  File "C:\Users\mssung\OneDrive - Webzen Inc\R2M도구\유료상점CL생성기\CLMaker_cashshop.py", line 142, in extract_data_cashshop
    sheet_names = pd.ExcelFile(fileName).sheet_names
  File "C:\Python39\lib\site-packages\pandas\io\excel\_base.py", line 1191, in __init__
    ext = inspect_excel_format(
  File "C:\Python39\lib\site-packages\pandas\io\excel\_base.py", line 1070, in inspect_excel_format
    with get_handle(
  File "C:\Python39\lib\site-packages\pandas\io\common.py", line 711, in get_handle
    handle = open(handle, ioargs.mode)
PermissionError: [Errno 13] Permission denied: '유료상점DATA_KR R2M.xlsx'

────────────────────────────────────────

user=mssung
date=2023-11-27 11:43:49
contents_name='유료상점'
doctype='TestCase'
date_text='2023-11-30'
Traceback (most recent call last):
  File "C:\Users\mssung\OneDrive - Webzen Inc\R2M도구\유료상점CL생성기\RDM.py", line 128, in make_process
    data = ClCash.extract_data_cashshop(data_file_name, date_text)
  File "C:\Users\mssung\OneDrive - Webzen Inc\R2M도구\유료상점CL생성기\CLMaker_cashshop.py", line 142, in extract_data_cashshop
    sheet_names = pd.ExcelFile(fileName).sheet_names
  File "C:\Python39\lib\site-packages\pandas\io\excel\_base.py", line 1191, in __init__
    ext = inspect_excel_format(
  File "C:\Python39\lib\site-packages\pandas\io\excel\_base.py", line 1070, in inspect_excel_format
    with get_handle(
  File "C:\Python39\lib\site-packages\pandas\io\common.py", line 711, in get_handle
    handle = open(handle, ioargs.mode)
PermissionError: [Errno 13] Permission denied: '유료상점DATA_KR R2M.xlsx'

────────────────────────────────────────

user=mssung
date=2023-11-24 19:19:05
contents_name='유료상점'
doctype='TestCase'
date_text='2023-11-30'
Traceback (most recent call last):
  File "C:\Users\mssung\OneDrive - Webzen Inc\R2M도구\유료상점CL생성기\RDM.py", line 129, in make_process
    result_file_name = ClCash.write_data_cashshop(data,result_path)
  File "C:\Users\mssung\OneDrive - Webzen Inc\R2M도구\유료상점CL생성기\CLMaker_cashshop.py", line 427, in write_data_cashshop
    result.loc[i,"Check List"] = f'{y.name} 관련 이미지 노출'
AttributeError: 'Sales' object has no attribute 'name'

────────────────────────────────────────

user=mssung
date=2023-11-23 15:05:40
contents_name='유료상점'
doctype='TestCase'
date_text='2023-09-23'
Traceback (most recent call last):
  File "C:\Users\mssung\OneDrive - Webzen Inc\R2M도구\유료상점CL생성기\RDM.py", line 128, in make_process
    data = ClCash.extract_data_cashshop(data_file_name, date_text)
  File "C:\Users\mssung\OneDrive - Webzen Inc\R2M도구\유료상점CL생성기\CLMaker_cashshop.py", line 142, in extract_data_cashshop
    sheet_names = pd.ExcelFile(fileName).sheet_names
  File "C:\Python39\lib\site-packages\pandas\io\excel\_base.py", line 1191, in __init__
    ext = inspect_excel_format(
  File "C:\Python39\lib\site-packages\pandas\io\excel\_base.py", line 1070, in inspect_excel_format
    with get_handle(
  File "C:\Python39\lib\site-packages\pandas\io\common.py", line 711, in get_handle
    handle = open(handle, ioargs.mode)
PermissionError: [Errno 13] Permission denied: '유료상점DATA_KR R2M.xlsx'


────────────────────────────────────────
user=mssung
date=2023-11-23 15:04:04
contents_name='유료상점'
doctype='TestCase'
date_text='2023-10-23'
Traceback (most recent call last):
  File "C:\Users\mssung\OneDrive - Webzen Inc\R2M도구\유료상점CL생성기\RDM.py", line 128, in make_process
    data = ClCash.extract_data_cashshop(data_file_name, date_text)
  File "C:\Users\mssung\OneDrive - Webzen Inc\R2M도구\유료상점CL생성기\CLMaker_cashshop.py", line 142, in extract_data_cashshop
    sheet_names = pd.ExcelFile(fileName).sheet_names
  File "C:\Python39\lib\site-packages\pandas\io\excel\_base.py", line 1191, in __init__
    ext = inspect_excel_format(
  File "C:\Python39\lib\site-packages\pandas\io\excel\_base.py", line 1070, in inspect_excel_format
    with get_handle(
  File "C:\Python39\lib\site-packages\pandas\io\common.py", line 711, in get_handle
    handle = open(handle, ioargs.mode)
PermissionError: [Errno 13] Permission denied: '유료상점DATA_KR R2M.xlsx'


────────────────────────────────────────
user=mssung
date=2023-11-23 15:03:40
contents_name='유료상점'
doctype='TestCase'
date_text='2023-10-23'
Traceback (most recent call last):
  File "C:\Users\mssung\OneDrive - Webzen Inc\R2M도구\유료상점CL생성기\RDM.py", line 128, in make_process
    data = ClCash.extract_data_cashshop(data_file_name, date_text)
  File "C:\Users\mssung\OneDrive - Webzen Inc\R2M도구\유료상점CL생성기\CLMaker_cashshop.py", line 142, in extract_data_cashshop
    sheet_names = pd.ExcelFile(fileName).sheet_names
  File "C:\Python39\lib\site-packages\pandas\io\excel\_base.py", line 1191, in __init__
    ext = inspect_excel_format(
  File "C:\Python39\lib\site-packages\pandas\io\excel\_base.py", line 1070, in inspect_excel_format
    with get_handle(
  File "C:\Python39\lib\site-packages\pandas\io\common.py", line 711, in get_handle
    handle = open(handle, ioargs.mode)
PermissionError: [Errno 13] Permission denied: '유료상점DATA_KR R2M.xlsx'


────────────────────────────────────────
user=mssung
date=2023-11-23 15:03:34
contents_name='유료상점'
doctype='TestCase'
date_text='2023-10-23'
Traceback (most recent call last):
  File "C:\Users\mssung\OneDrive - Webzen Inc\R2M도구\유료상점CL생성기\RDM.py", line 128, in make_process
    data = ClCash.extract_data_cashshop(data_file_name, date_text)
  File "C:\Users\mssung\OneDrive - Webzen Inc\R2M도구\유료상점CL생성기\CLMaker_cashshop.py", line 142, in extract_data_cashshop
    sheet_names = pd.ExcelFile(fileName).sheet_names
  File "C:\Python39\lib\site-packages\pandas\io\excel\_base.py", line 1191, in __init__
    ext = inspect_excel_format(
  File "C:\Python39\lib\site-packages\pandas\io\excel\_base.py", line 1070, in inspect_excel_format
    with get_handle(
  File "C:\Python39\lib\site-packages\pandas\io\common.py", line 711, in get_handle
    handle = open(handle, ioargs.mode)
PermissionError: [Errno 13] Permission denied: '유료상점DATA_KR R2M.xlsx'


────────────────────────────────────────
date=2023-10-31 10:25:46
user=mssung
Traceback (most recent call last):
  File "C:\Users\mssung\OneDrive - Webzen Inc\R2M도구\유료상점CL생성기\RDM.py", line 131, in make_process
    ClCash.postprocess_cashshop(result_file_name)
  File "C:\Users\mssung\OneDrive - Webzen Inc\R2M도구\유료상점CL생성기\CLMaker_cashshop.py", line 812, in postprocess_cashshop
    ws.merge_cells("B"+str(startRow_B)+":B"+str(lastRow))
  File "C:\Python39\lib\site-packages\openpyxl\worksheet\worksheet.py", line 597, in merge_cells
    mcr = MergedCellRange(self, range_string)
  File "C:\Python39\lib\site-packages\openpyxl\worksheet\merge.py", line 68, in __init__
    super().__init__(range_string=coord)
  File "C:\Python39\lib\site-packages\openpyxl\worksheet\cell_range.py", line 57, in __init__
    self.min_row = min_row
  File "C:\Python39\lib\site-packages\openpyxl\descriptors\base.py", line 111, in __set__
    raise ValueError('Min value is {0}'.format(self.min))
ValueError: Min value is 1

date=2023-10-31 10:27:36
user=mssung
Traceback (most recent call last):
  File "C:\Users\mssung\OneDrive - Webzen Inc\R2M도구\유료상점CL생성기\RDM.py", line 131, in make_process
    ClCash.postprocess_cashshop(result_file_name)
  File "C:\Users\mssung\OneDrive - Webzen Inc\R2M도구\유료상점CL생성기\CLMaker_cashshop.py", line 812, in postprocess_cashshop
    ws.merge_cells("B"+str(startRow_B)+":B"+str(lastRow))
  File "C:\Python39\lib\site-packages\openpyxl\worksheet\worksheet.py", line 597, in merge_cells
    mcr = MergedCellRange(self, range_string)
  File "C:\Python39\lib\site-packages\openpyxl\worksheet\merge.py", line 68, in __init__
    super().__init__(range_string=coord)
  File "C:\Python39\lib\site-packages\openpyxl\worksheet\cell_range.py", line 57, in __init__
    self.min_row = min_row
  File "C:\Python39\lib\site-packages\openpyxl\descriptors\base.py", line 111, in __set__
    raise ValueError('Min value is {0}'.format(self.min))
ValueError: Min value is 1

            date=2023-11-03 12:06:39
            user=mssung
            contents_name='이벤트'
doctype='TestCase'
date_text='2023-11-14'
Traceback (most recent call last):
  File "C:\Users\mssung\OneDrive - Webzen Inc\R2M도구\유료상점CL생성기\RDM.py", line 140, in make_process
    data = ClEvent.extract_data(data_file_name,date_text)
  File "C:\Users\mssung\OneDrive - Webzen Inc\R2M도구\유료상점CL생성기\CLMaker_Event.py", line 103, in extract_data
    sheet_names = pd.read_excel(fileName, sheet_name=None).keys()
  File "C:\Python39\lib\site-packages\pandas\util\_decorators.py", line 311, in wrapper
    return func(*args, **kwargs)
  File "C:\Python39\lib\site-packages\pandas\io\excel\_base.py", line 364, in read_excel
    io = ExcelFile(io, storage_options=storage_options, engine=engine)
  File "C:\Python39\lib\site-packages\pandas\io\excel\_base.py", line 1191, in __init__
    ext = inspect_excel_format(
  File "C:\Python39\lib\site-packages\pandas\io\excel\_base.py", line 1070, in inspect_excel_format
    with get_handle(
  File "C:\Python39\lib\site-packages\pandas\io\common.py", line 711, in get_handle
    handle = open(handle, ioargs.mode)
PermissionError: [Errno 13] Permission denied: '이벤트DATA_TW R2M.xlsx'

            date=2023-11-13 10:31:37
            user=mssung
            contents_name='유료상점'
doctype='CheckList'
date_text='2024-11-09'
Traceback (most recent call last):
  File "C:\Users\mssung\OneDrive - Webzen Inc\R2M도구\유료상점CL생성기\RDM.py", line 132, in make_process
    ClCash.postprocess_cashshop(result_file_name)
  File "C:\Users\mssung\OneDrive - Webzen Inc\R2M도구\유료상점CL생성기\CLMaker_cashshop.py", line 815, in postprocess_cashshop
    ws.merge_cells("B"+str(startRow_B)+":B"+str(lastRow))
  File "C:\Python39\lib\site-packages\openpyxl\worksheet\worksheet.py", line 597, in merge_cells
    mcr = MergedCellRange(self, range_string)
  File "C:\Python39\lib\site-packages\openpyxl\worksheet\merge.py", line 68, in __init__
    super().__init__(range_string=coord)
  File "C:\Python39\lib\site-packages\openpyxl\worksheet\cell_range.py", line 57, in __init__
    self.min_row = min_row
  File "C:\Python39\lib\site-packages\openpyxl\descriptors\base.py", line 111, in __set__
    raise ValueError('Min value is {0}'.format(self.min))
ValueError: Min value is 1

            date=2023-11-13 11:33:22
            user=mssung
            contents_name='유료상점'
doctype='TestCase'
date_text='2023-11-14'
Traceback (most recent call last):
  File "C:\Users\mssung\OneDrive - Webzen Inc\R2M도구\유료상점CL생성기\RDM.py", line 128, in make_process
    data = ClCash.extract_data_cashshop(data_file_name, date_text)
  File "C:\Users\mssung\OneDrive - Webzen Inc\R2M도구\유료상점CL생성기\CLMaker_cashshop.py", line 204, in extract_data_cashshop
    a.pkgID = int(tempDf.loc[0,"CashShopID"])
ValueError: invalid literal for int() with base 10: 'TWD 1000028'

                                                                                    